Error occurred at 2025-09-18 13:46:31.976712: Improper token has been passed.
Traceback (most recent call last):
  File "/home/lia_lazhannya/.pyenv/versions/3.12.11/lib/python3.12/site-packages/discord/http.py", line 839, in static_login
    data = await self.request(Route('GET', '/users/@me'))
           ^^^^^^^^^^^^^^^^^^^^^^^^^^^^^^^^^^^^^^^^^^^^^^
  File "/home/lia_lazhannya/.pyenv/versions/3.12.11/lib/python3.12/site-packages/discord/http.py", line 773, in request
    raise HTTPException(response, data)
discord.errors.HTTPException: 401 Unauthorized (error code: 0): 401: Unauthorized

The above exception was the direct cause of the following exception:

Traceback (most recent call last):
  File "/home/lia_lazhannya/workspace/github.com/lazhannya/BeanBot/main.py", line 151, in <module>
    bot.run(token, log_level=logging.DEBUG)
  File "/home/lia_lazhannya/.pyenv/versions/3.12.11/lib/python3.12/site-packages/discord/client.py", line 929, in run
    asyncio.run(runner())
  File "/home/lia_lazhannya/.pyenv/versions/3.12.11/lib/python3.12/asyncio/runners.py", line 195, in run
    return runner.run(main)
           ^^^^^^^^^^^^^^^^
  File "/home/lia_lazhannya/.pyenv/versions/3.12.11/lib/python3.12/asyncio/runners.py", line 118, in run
    return self._loop.run_until_complete(task)
           ^^^^^^^^^^^^^^^^^^^^^^^^^^^^^^^^^^^
  File "/home/lia_lazhannya/.pyenv/versions/3.12.11/lib/python3.12/asyncio/base_events.py", line 691, in run_until_complete
    return future.result()
           ^^^^^^^^^^^^^^^
  File "/home/lia_lazhannya/.pyenv/versions/3.12.11/lib/python3.12/site-packages/discord/client.py", line 918, in runner
    await self.start(token, reconnect=reconnect)
  File "/home/lia_lazhannya/.pyenv/versions/3.12.11/lib/python3.12/site-packages/discord/client.py", line 846, in start
    await self.login(token)
  File "/home/lia_lazhannya/.pyenv/versions/3.12.11/lib/python3.12/site-packages/discord/client.py", line 675, in login
    data = await self.http.static_login(token)
           ^^^^^^^^^^^^^^^^^^^^^^^^^^^^^^^^^^^
  File "/home/lia_lazhannya/.pyenv/versions/3.12.11/lib/python3.12/site-packages/discord/http.py", line 843, in static_login
    raise LoginFailure('Improper token has been passed.') from exc
discord.errors.LoginFailure: Improper token has been passed.

---
